Workbook

Sheet Teams
A1: Team Names | C1: Team 1 | D1: Team 2 | E1: Team 3 | F1: Team 4 | G1: Team 5 | H1: Team 6 | I1: Team 7 | J1: Team 8
A2: Schedule format | B2: team-ref
A3: League | B3: Eight Team Team-Ref League

Sheet Schedule Generator
B2: Team 1 | C2: Team 2 | D2: Team 3 | E2: Team 4 | F2: Team 5 | G2: Team 6 | H2: Team 7 | I2: Team 8
A3: Team 1 | B3: - | C3: 9 | D3: 9 | E3: 9 | F3: 9 | G3: 8 | H3: 8 | I3: 8
A4: Team 2 | B4: 9 | C4: - | D4: 9 | E4: 9 | F4: 8 | G4: 9 | H4: 8 | I4: 8
A5: Team 3 | B5: 9 | C5: 9 | D5: - | E5: 8 | F5: 9 | G5: 8 | H5: 9 | I5: 8
A6: Team 4 | B6: 9 | C6: 9 | D6: 8 | E6: - | F6: 8 | G6: 9 | H6: 8 | I6: 9
A7: Team 5 | B7: 9 | C7: 8 | D7: 9 | E7: 8 | F7: - | G7: 8 | H7: 9 | I7: 9
A8: Team 6 | B8: 8 | C8: 9 | D8: 8 | E8: 9 | F8: 8 | G8: - | H8: 9 | I8: 9
A9: Team 7 | B9: 8 | C9: 8 | D9: 9 | E9: 8 | F9: 9 | G9: 9 | H9: - | I9: 9
A10: Team 8 | B10: 8 | C10: 8 | D10: 8 | E10: 9 | F10: 9 | G10: 9 | H10: 9 | I10: -

Sheet League Standings
A1: LEAGUE STANDINGS
A2: Team Name | B2: Points For | C2: Points Against | D2: Point Differential
A3: =INDEX(A17:A24,MATCH(ROUND(LARGE(C17:C24,1),8),C17:C24,0)) | B3: =INDEX(B17:B24,MATCH(ROUND(LARGE(C17:C24,1),8),C17:C24,0)) | C3: =INDEX(E17:E24,MATCH(ROUND(LARGE(C17:C24,1),8),C17:C24,0)) | D3: =B3-C3
A4: =INDEX(A17:A24,MATCH(ROUND(LARGE(C17:C24,2),8),C17:C24,0)) | B4: =INDEX(B17:B24,MATCH(ROUND(LARGE(C17:C24,2),8),C17:C24,0)) | C4: =INDEX(E17:E24,MATCH(ROUND(LARGE(C17:C24,2),8),C17:C24,0)) | D4: =B4-C4
A5: =INDEX(A17:A24,MATCH(ROUND(LARGE(C17:C24,3),8),C17:C24,0)) | B5: =INDEX(B17:B24,MATCH(ROUND(LARGE(C17:C24,3),8),C17:C24,0)) | C5: =INDEX(E17:E24,MATCH(ROUND(LARGE(C17:C24,3),8),C17:C24,0)) | D5: =B5-C5
A6: =INDEX(A17:A24,MATCH(ROUND(LARGE(C17:C24,4),8),C17:C24,0)) | B6: =INDEX(B17:B24,MATCH(ROUND(LARGE(C17:C24,4),8),C17:C24,0)) | C6: =INDEX(E17:E24,MATCH(ROUND(LARGE(C17:C24,4),8),C17:C24,0)) | D6: =B6-C6
A7: =INDEX(A17:A24,MATCH(ROUND(LARGE(C17:C24,5),8),C17:C24,0)) | B7: =INDEX(B17:B24,MATCH(ROUND(LARGE(C17:C24,5),8),C17:C24,0)) | C7: =INDEX(E17:E24,MATCH(ROUND(LARGE(C17:C24,5),8),C17:C24,0)) | D7: =B7-C7
A8: =INDEX(A17:A24,MATCH(ROUND(LARGE(C17:C24,6),8),C17:C24,0)) | B8: =INDEX(B17:B24,MATCH(ROUND(LARGE(C17:C24,6),8),C17:C24,0)) | C8: =INDEX(E17:E24,MATCH(ROUND(LARGE(C17:C24,6),8),C17:C24,0)) | D8: =B8-C8
A9: =INDEX(A17:A24,MATCH(ROUND(LARGE(C17:C24,7),8),C17:C24,0)) | B9: =INDEX(B17:B24,MATCH(ROUND(LARGE(C17:C24,7),8),C17:C24,0)) | C9: =INDEX(E17:E24,MATCH(ROUND(LARGE(C17:C24,7),8),C17:C24,0)) | D9: =B9-C9
A10: =INDEX(A17:A24,MATCH(ROUND(LARGE(C17:C24,8),8),C17:C24,0)) | B10: =INDEX(B17:B24,MATCH(ROUND(LARGE(C17:C24,8),8),C17:C24,0)) | C10: =INDEX(E17:E24,MATCH(ROUND(LARGE(C17:C24,8),8),C17:C24,0)) | D10: =B10-C10
A11: Week # | B11: 0
A16: Teams | B16: Wins | E16: Losses
A17: Team 1 | B17: ='Week 1 Schedule'!B45+'Week 2 Schedule'!B45+'Week 3 Schedule'!B45+'Week 4 Schedule'!B45+'Week 5 Schedule'!B45+'Week 6 Schedule'!B45 | C17: =ROUND(B17+17/10000,8) | E17: ='Week 1 Schedule'!C45+'Week 2 Schedule'!C45+'Week 3 Schedule'!C45+'Week 4 Schedule'!C45+'Week 5 Schedule'!C45+'Week 6 Schedule'!C45
A18: Team 2 | B18: ='Week 1 Schedule'!B46+'Week 2 Schedule'!B46+'Week 3 Schedule'!B46+'Week 4 Schedule'!B46+'Week 5 Schedule'!B46+'Week 6 Schedule'!B46 | C18: =ROUND(B18+18/10000,8) | E18: ='Week 1 Schedule'!C46+'Week 2 Schedule'!C46+'Week 3 Schedule'!C46+'Week 4 Schedule'!C46+'Week 5 Schedule'!C46+'Week 6 Schedule'!C46
A19: Team 3 | B19: ='Week 1 Schedule'!B47+'Week 2 Schedule'!B47+'Week 3 Schedule'!B47+'Week 4 Schedule'!B47+'Week 5 Schedule'!B47+'Week 6 Schedule'!B47 | C19: =ROUND(B19+19/10000,8) | E19: ='Week 1 Schedule'!C47+'Week 2 Schedule'!C47+'Week 3 Schedule'!C47+'Week 4 Schedule'!C47+'Week 5 Schedule'!C47+'Week 6 Schedule'!C47
A20: Team 4 | B20: ='Week 1 Schedule'!B48+'Week 2 Schedule'!B48+'Week 3 Schedule'!B48+'Week 4 Schedule'!B48+'Week 5 Schedule'!B48+'Week 6 Schedule'!B48 | C20: =ROUND(B20+20/10000,8) | E20: ='Week 1 Schedule'!C48+'Week 2 Schedule'!C48+'Week 3 Schedule'!C48+'Week 4 Schedule'!C48+'Week 5 Schedule'!C48+'Week 6 Schedule'!C48
A21: Team 5 | B21: ='Week 1 Schedule'!B49+'Week 2 Schedule'!B49+'Week 3 Schedule'!B49+'Week 4 Schedule'!B49+'Week 5 Schedule'!B49+'Week 6 Schedule'!B49 | C21: =ROUND(B21+21/10000,8) | E21: ='Week 1 Schedule'!C49+'Week 2 Schedule'!C49+'Week 3 Schedule'!C49+'Week 4 Schedule'!C49+'Week 5 Schedule'!C49+'Week 6 Schedule'!C49
A22: Team 6 | B22: ='Week 1 Schedule'!B50+'Week 2 Schedule'!B50+'Week 3 Schedule'!B50+'Week 4 Schedule'!B50+'Week 5 Schedule'!B50+'Week 6 Schedule'!B50 | C22: =ROUND(B22+22/10000,8) | E22: ='Week 1 Schedule'!C50+'Week 2 Schedule'!C50+'Week 3 Schedule'!C50+'Week 4 Schedule'!C50+'Week 5 Schedule'!C50+'Week 6 Schedule'!C50
A23: Team 7 | B23: ='Week 1 Schedule'!B51+'Week 2 Schedule'!B51+'Week 3 Schedule'!B51+'Week 4 Schedule'!B51+'Week 5 Schedule'!B51+'Week 6 Schedule'!B51 | C23: =ROUND(B23+23/10000,8) | E23: ='Week 1 Schedule'!C51+'Week 2 Schedule'!C51+'Week 3 Schedule'!C51+'Week 4 Schedule'!C51+'Week 5 Schedule'!C51+'Week 6 Schedule'!C51
A24: Team 8 | B24: ='Week 1 Schedule'!B52+'Week 2 Schedule'!B52+'Week 3 Schedule'!B52+'Week 4 Schedule'!B52+'Week 5 Schedule'!B52+'Week 6 Schedule'!B52 | C24: =ROUND(B24+24/10000,8) | E24: ='Week 1 Schedule'!C52+'Week 2 Schedule'!C52+'Week 3 Schedule'!C52+'Week 4 Schedule'!C52+'Week 5 Schedule'!C52+'Week 6 Schedule'!C52
A27: Head-to-head wins (row vs column; higher score wins the game)
B28: Team 1 | C28: Team 2 | D28: Team 3 | E28: Team 4 | F28: Team 5 | G28: Team 6 | H28: Team 7 | I28: Team 8
A29: Team 1 | B29: — | C29: =(SUMPRODUCT(--('Week 1 Schedule'!$B$2:$B$500=$A29),--('Week 1 Schedule'!$D$2:$D$500=$C$28),--('Week 1 Schedule'!$C$2:$C$500>'Week 1 Schedule'!$E$2:$E$500))+SUMPRODUCT(--('Week 1 Schedule'!$B$2:$B$500=$C$28),--('Week 1 Schedule'!$D$2:$D$500=$A29),--('Week 1 Schedule'!$E$2:$E$500>'Week 1 Schedule'!$C$2:$C$500)))+(SUMPRODUCT(--('Week 1 Schedule'!$G$2:$G$500=$A29),--('Week 1 Schedule'!$I$2:$I$500=$C$28),--('Week 1 Schedule'!$H$2:$H$500>'Week 1 Schedule'!$J$2:$J$500))+SUMPRODUCT(--('Week 1 Schedule'!$G$2:$G$500=$C$28),--('Week 1 Schedule'!$I$2:$I$500=$A29),--('Week 1 Schedule'!$J$2:$J$500>'Week 1 Schedule'!$H$2:$H$500)))+(SUMPRODUCT(--('Week 2 Schedule'!$B$2:$B$500=$A29),--('Week 2 Schedule'!$D$2:$D$500=$C$28),--('Week 2 Schedule'!$C$2:$C$500>'Week 2 Schedule'!$E$2:$E$500))+SUMPRODUCT(--('Week 2 Schedule'!$B$2:$B$500=$C$28),--('Week 2 Schedule'!$D$2:$D$500=$A29),--('Week 2 Schedule'!$E$2:$E$500>'Week 2 Schedule'!$C$2:$C$500)))+(SUMPRODUCT(--('Week 2 Schedule'!$G$2:$G$500=$A29),--('Week 2 Schedule'!$I$2:$I$500=$C$28),--('Week 2 Schedule'!$H$2:$H$500>'Week 2 Schedule'!$J$2:$J$500))+SUMPRODUCT(--('Week 2 Schedule'!$G$2:$G$500=$C$28),--('Week 2 Schedule'!$I$2:$I$500=$A29),--('Week 2 Schedule'!$J$2:$J$500>'Week 2 Schedule'!$H$2:$H$500)))+(SUMPRODUCT(--('Week 3 Schedule'!$B$2:$B$500=$A29),--('Week 3 Schedule'!$D$2:$D$500=$C$28),--('Week 3 Schedule'!$C$2:$C$500>'Week 3 Schedule'!$E$2:$E$500))+SUMPRODUCT(--('Week 3 Schedule'!$B$2:$B$500=$C$28),--('Week 3 Schedule'!$D$2:$D$500=$A29),--('Week 3 Schedule'!$E$2:$E$500>'Week 3 Schedule'!$C$2:$C$500)))+(SUMPRODUCT(--('Week 3 Schedule'!$G$2:$G$500=$A29),--('Week 3 Schedule'!$I$2:$I$500=$C$28),--('Week 3 Schedule'!$H$2:$H$500>'Week 3 Schedule'!$J$2:$J$500))+SUMPRODUCT(--('Week 3 Schedule'!$G$2:$G$500=$C$28),--('Week 3 Schedule'!$I$2:$I$500=$A29),--('Week 3 Schedule'!$J$2:$J$500>'Week 3 Schedule'!$H$2:$H$500)))+(SUMPRODUCT(--('Week 4 Schedule'!$B$2:$B$500=$A29),--('Week 4 Schedule'!$D$2:$D$500=$C$28),--('Week 4 Schedule'!$C$2:$C$500>'Week 4 Schedule'!$E$2:$E$500))+SUMPRODUCT(--('Week 4 Schedule'!$B$2:$B$500=$C$28),--('Week 4 Schedule'!$D$2:$D$500=$A29),--('Week 4 Schedule'!$E$2:$E$500>'Week 4 Schedule'!$C$2:$C$500)))+(SUMPRODUCT(--('Week 4 Schedule'!$G$2:$G$500=$A29),--('Week 4 Schedule'!$I$2:$I$500=$C$28),--('Week 4 Schedule'!$H$2:$H$500>'Week 4 Schedule'!$J$2:$J$500))+SUMPRODUCT(--('Week 4 Schedule'!$G$2:$G$500=$C$28),--('Week 4 Schedule'!$I$2:$I$500=$A29),--('Week 4 Schedule'!$J$2:$J$500>'Week 4 Schedule'!$H$2:$H$500)))+(SUMPRODUCT(--('Week 5 Schedule'!$B$2:$B$500=$A29),--('Week 5 Schedule'!$D$2:$D$500=$C$28),--('Week 5 Schedule'!$C$2:$C$500>'Week 5 Schedule'!$E$2:$E$500))+SUMPRODUCT(--('Week 5 Schedule'!$B$2:$B$500=$C$28),--('Week 5 Schedule'!$D$2:$D$500=$A29),--('Week 5 Schedule'!$E$2:$E$500>'Week 5 Schedule'!$C$2:$C$500)))+(SUMPRODUCT(--('Week 5 Schedule'!$G$2:$G$500=$A29),--('Week 5 Schedule'!$I$2:$I$500=$C$28),--('Week 5 Schedule'!$H$2:$H$500>'Week 5 Schedule'!$J$2:$J$500))+SUMPRODUCT(--('Week 5 Schedule'!$G$2:$G$500=$C$28),--('Week 5 Schedule'!$I$2:$I$500=$A29),--('Week 5 Schedule'!$J$2:$J$500>'Week 5 Schedule'!$H$2:$H$500)))+(SUMPRODUCT(--('Week 6 Schedule'!$B$2:$B$500=$A29),--('Week 6 Schedule'!$D$2:$D$500=$C$28),--('Week 6 Schedule'!$C$2:$C$500>'Week 6 Schedule'!$E$2:$E$500))+SUMPRODUCT(--('Week 6 Schedule'!$B$2:$B$500=$C$28),--('Week 6 Schedule'!$D$2:$D$500=$A29),--('Week 6 Schedule'!$E$2:$E$500>'Week 6 Schedule'!$C$2:$C$500)))+(SUMPRODUCT(--('Week 6 Schedule'!$G$2:$G$500=$A29),--('Week 6 Schedule'!$I$2:$I$500=$C$28),--('Week 6 Schedule'!$H$2:$H$500>'Week 6 Schedule'!$J$2:$J$500))+SUMPRODUCT(--('Week 6 Schedule'!$G$2:$G$500=$C$28),--('Week 6 Schedule'!$I$2:$I$500=$A29),--('Week 6 Schedule'!$J$2:$J$500>'Week 6 Schedule'!$H$2:$H$500))) | D29: =(SUMPRODUCT(--('Week 1 Schedule'!$B$2:$B$500=$A29),--('Week 1 Schedule'!$D$2:$D$500=$D$28),--('Week 1 Schedule'!$C$2:$C$500>'Week 1 Schedule'!$E$2:$E$500))+SUMPRODUCT(--('Week 1 Schedule'!$B$2:$B$500=$D$28),--('Week 1 Schedule'!$D$2:$D$500=$A29),--('Week 1 Schedule'!$E$2:$E$500>'Week 1 Schedule'!$C$2:$C$500)))+(SUMPRODUCT(--('Week 1 Schedule'!$G$2:$G$500=$A29),--('Week 1 Schedule'!$I$2:$I$500=$D$28),--('Week 1 Schedule'!$H$2:$H$500>'Week 1 Schedule'!$J$2:$J$500))+SUMPRODUCT(--('Week 1 Schedule'!$G$2:$G$500=$D$28),--('Week 1 Schedule'!$I$2:$I$500=$A29),--('Week 1 Schedule'!$J$2:$J$500>'Week 1 Schedule'!$H$2:$H$500)))+(SUMPRODUCT(--('Week 2 Schedule'!$B$2:$B$500=$A29),--('Week 2 Schedule'!$D$2:$D$500=$D$28),--('Week 2 Schedule'!$C$2:$C$500>'Week 2 Schedule'!$E$2:$E$500))+SUMPRODUCT(--('Week 2 Schedule'!$B$2:$B$500=$D$28),--('Week 2 Schedule'!$D$2:$D$500=$A29),--('Week 2 Schedule'!$E$2:$E$500>'Week 2 Schedule'!$C$2:$C$500)))+(SUMPRODUCT(--('Week 2 Schedule'!$G$2:$G$500=$A29),--('Week 2 Schedule'!$I$2:$I$500=$D$28),--('Week 2 Schedule'!$H$2:$H$500>'Week 2 Schedule'!$J$2:$J$500))+SUMPRODUCT(--('Week 2 Schedule'!$G$2:$G$500=$D$28),--('Week 2 Schedule'!$I$2:$I$500=$A29),--('Week 2 Schedule'!$J$2:$J$500>'Week 2 Schedule'!$H$2:$H$500)))+(SUMPRODUCT(--('Week 3 Schedule'!$B$2:$B$500=$A29),--('Week 3 Schedule'!$D$2:$D$500=$D$28),--('Week 3 Schedule'!$C$2:$C$500>'Week 3 Schedule'!$E$2:$E$500))+SUMPRODUCT(--('Week 3 Schedule'!$B$2:$B$500=$D$28),--('Week 3 Schedule'!$D$2:$D$500=$A29),--('Week 3 Schedule'!$E$2:$E$500>'Week 3 Schedule'!$C$2:$C$500)))+(SUMPRODUCT(--('Week 3 Schedule'!$G$2:$G$500=$A29),--('Week 3 Schedule'!$I$2:$I$500=$D$28),--('Week 3 Schedule'!$H$2:$H$500>'Week 3 Schedule'!$J$2:$J$500))+SUMPRODUCT(--('Week 3 Schedule'!$G$2:$G$500=$D$28),--('Week 3 Schedule'!$I$2:$I$500=$A29),--('Week 3 Schedule'!$J$2:$J$500>'Week 3 Schedule'!$H$2:$H$500)))+(SUMPRODUCT(--('Week 4 Schedule'!$B$2:$B$500=$A29),--('Week 4 Schedule'!$D$2:$D$500=$D$28),--('Week 4 Schedule'!$C$2:$C$500>'Week 4 Schedule'!$E$2:$E$500))+SUMPRODUCT(--('Week 4 Schedule'!$B$2:$B$500=$D$28),--('Week 4 Schedule'!$D$2:$D$500=$A29),--('Week 4 Schedule'!$E$2:$E$500>'Week 4 Schedule'!$C$2:$C$500)))+(SUMPRODUCT(--('Week 4 Schedule'!$G$2:$G$500=$A29),--('Week 4 Schedule'!$I$2:$I$500=$D$28),--('Week 4 Schedule'!$H$2:$H$500>'Week 4 Schedule'!$J$2:$J$500))+SUMPRODUCT(--('Week 4 Schedule'!$G$2:$G$500=$D$28),--('Week 4 Schedule'!$I$2:$I$500=$A29),--('Week 4 Schedule'!$J$2:$J$500>'Week 4 Schedule'!$H$2:$H$500)))+(SUMPRODUCT(--('Week 5 Schedule'!$B$2:$B$500=$A29),--('Week 5 Schedule'!$D$2:$D$500=$D$28),--('Week 5 Schedule'!$C$2:$C$500>'Week 5 Schedule'!$E$2:$E$500))+SUMPRODUCT(--('Week 5 Schedule'!$B$2:$B$500=$D$28),--('Week 5 Schedule'!$D$2:$D$500=$A29),--('Week 5 Schedule'!$E$2:$E$500>'Week 5 Schedule'!$C$2:$C$500)))+(SUMPRODUCT(--('Week 5 Schedule'!$G$2:$G$500=$A29),--('Week 5 Schedule'!$I$2:$I$500=$D$28),--('Week 5 Schedule'!$H$2:$H$500>'Week 5 Schedule'!$J$2:$J$500))+SUMPRODUCT(--('Week 5 Schedule'!$G$2:$G$500=$D$28),--('Week 5 Schedule'!$I$2:$I$500=$A29),--('Week 5 Schedule'!$J$2:$J$500>'Week 5 Schedule'!$H$2:$H$500)))+(SUMPRODUCT(--('Week 6 Schedule'!$B$2:$B$500=$A29),--('Week 6 Schedule'!$D$2:$D$500=$D$28),--('Week 6 Schedule'!$C$2:$C$500>'Week 6 Schedule'!$E$2:$E$500))+SUMPRODUCT(--('Week 6 Schedule'!$B$2:$B$500=$D$28),--('Week 6 Schedule'!$D$2:$D$500=$A29),--('Week 6 Schedule'!$E$2:$E$500>'Week 6 Schedule'!$C$2:$C$500)))+(SUMPRODUCT(--('Week 6 Schedule'!$G$2:$G$500=$A29),--('Week 6 Schedule'!$I$2:$I$500=$D$28),--('Week 6 Schedule'!$H$2:$H$500>'Week 6 Schedule'!$J$2:$J$500))+SUMPRODUCT(--('Week 6 Schedule'!$G$2:$G$500=$D$28),--('Week 6 Schedule'!$I$2:$I$500=$A29),--('Week 6 Schedule'!$J$2:$J$500>'Week 6 Schedule'!$H$2:$H$500))) | E29: =(SUMPRODUCT(--('Week 1 Schedule'!$B$2:$B$500=$A29),--('Week 1 Schedule'!$D$2:$D$500=$E$28),--('Week 1 Schedule'!$C$2:$C$500>'Week 1 Schedule'!$E$2:$E$500))+SUMPRODUCT(--('Week 1 Schedule'!$B$2:$B$500=$E$28),--('Week 1 Schedule'!$D$2:$D$500=$A29),--('Week 1 Schedule'!$E$2:$E$500>'Week 1 Schedule'!$C$2:$C$500)))+(SUMPRODUCT(--('Week 1 Schedule'!$G$2:$G$500=$A29),--('Week 1 Schedule'!$I$2:$I$500=$E$28),--('Week 1 Schedule'!$H$2:$H$500>'Week 1 Schedule'!$J$2:$J$500))+SUMPRODUCT(--('Week 1 Schedule'!$G$2:$G$500=$E$28),--('Week 1 Schedule'!$I$2:$I$500=$A29),--('Week 1 Schedule'!$J$2:$J$500>'Week 1 Schedule'!$H$2:$H$500)))+(SUMPRODUCT(--('Week 2 Schedule'!$B$2:$B$500=$A29),--('Week 2 Schedule'!$D$2:$D$500=$E$28),--('Week 2 Schedule'!$C$2:$C$500>'Week 2 Schedule'!$E$2:$E$500))+SUMPRODUCT(--('Week 2 Schedule'!$B$2:$B$500=$E$28),--('Week 2 Schedule'!$D$2:$D$500=$A29),--('Week 2 Schedule'!$E$2:$E$500>'Week 2 Schedule'!$C$2:$C$500)))+(SUMPRODUCT(--('Week 2 Schedule'!$G$2:$G$500=$A29),--('Week 2 Schedule'!$I$2:$I$500=$E$28),--('Week 2 Schedule'!$H$2:$H$500>'Week 2 Schedule'!$J$2:$J$500))+SUMPRODUCT(--('Week 2 Schedule'!$G$2:$G$500=$E$28),--('Week 2 Schedule'!$I$2:$I$500=$A29),--('Week 2 Schedule'!$J$2:$J$500>'Week 2 Schedule'!$H$2:$H$500)))+(SUMPRODUCT(--('Week 3 Schedule'!$B$2:$B$500=$A29),--('Week 3 Schedule'!$D$2:$D$500=$E$28),--('Week 3 Schedule'!$C$2:$C$500>'Week 3 Schedule'!$E$2:$E$500))+SUMPRODUCT(--('Week 3 Schedule'!$B$2:$B$500=$E$28),--('Week 3 Schedule'!$D$2:$D$500=$A29),--('Week 3 Schedule'!$E$2:$E$500>'Week 3 Schedule'!$C$2:$C$500)))+(SUMPRODUCT(--('Week 3 Schedule'!$G$2:$G$500=$A29),--('Week 3 Schedule'!$I$2:$I$500=$E$28),--('Week 3 Schedule'!$H$2:$H$500>'Week 3 Schedule'!$J$2:$J$500))+SUMPRODUCT(--('Week 3 Schedule'!$G$2:$G$500=$E$28),--('Week 3 Schedule'!$I$2:$I$500=$A29),--('Week 3 Schedule'!$J$2:$J$500>'Week 3 Schedule'!$H$2:$H$500)))+(SUMPRODUCT(--('Week 4 Schedule'!$B$2:$B$500=$A29),--('Week 4 Schedule'!$D$2:$D$500=$E$28),--('Week 4 Schedule'!$C$2:$C$500>'Week 4 Schedule'!$E$2:$E$500))+SUMPRODUCT(--('Week 4 Schedule'!$B$2:$B$500=$E$28),--('Week 4 Schedule'!$D$2:$D$500=$A29),--('Week 4 Schedule'!$E$2:$E$500>'Week 4 Schedule'!$C$2:$C$500)))+(SUMPRODUCT(--('Week 4 Schedule'!$G$2:$G$500=$A29),--('Week 4 Schedule'!$I$2:$I$500=$E$28),--('Week 4 Schedule'!$H$2:$H$500>'Week 4 Schedule'!$J$2:$J$500))+SUMPRODUCT(--('Week 4 Schedule'!$G$2:$G$500=$E$28),--('Week 4 Schedule'!$I$2:$I$500=$A29),--('Week 4 Schedule'!$J$2:$J$500>'Week 4 Schedule'!$H$2:$H$500)))+(SUMPRODUCT(--('Week 5 Schedule'!$B$2:$B$500=$A29),--('Week 5 Schedule'!$D$2:$D$500=$E$28),--('Week 5 Schedule'!$C$2:$C$500>'Week 5 Schedule'!$E$2:$E$500))+SUMPRODUCT(--('Week 5 Schedule'!$B$2:$B$500=$E$28),--('Week 5 Schedule'!$D$2:$D$500=$A29),--('Week 5 Schedule'!$E$2:$E$500>'Week 5 Schedule'!$C$2:$C$500)))+(SUMPRODUCT(--('Week 5 Schedule'!$G$2:$G$500=$A29),--('Week 5 Schedule'!$I$2:$I$500=$E$28),--('Week 5 Schedule'!$H$2:$H$500>'Week 5 Schedule'!$J$2:$J$500))+SUMPRODUCT(--('Week 5 Schedule'!$G$2:$G$500=$E$28),--('Week 5 Schedule'!$I$2:$I$500=$A29),--('Week 5 Schedule'!$J$2:$J$500>'Week 5 Schedule'!$H$2:$H$500)))+(SUMPRODUCT(--('Week 6 Schedule'!$B$2:$B$500=$A29),--('Week 6 Schedule'!$D$2:$D$500=$E$28),--('Week 6 Schedule'!$C$2:$C$500>'Week 6 Schedule'!$E$2:$E$500))+SUMPRODUCT(--('Week 6 Schedule'!$B$2:$B$500=$E$28),--('Week 6 Schedule'!$D$2:$D$500=$A29),--('Week 6 Schedule'!$E$2:$E$500>'Week 6 Schedule'!$C$2:$C$500)))+(SUMPRODUCT(--('Week 6 Schedule'!$G$2:$G$500=$A29),--('Week 6 Schedule'!$I$2:$I$500=$E$28),--('Week 6 Schedule'!$H$2:$H$500>'Week 6 Schedule'!$J$2:$J$500))+SUMPRODUCT(--('Week 6 Schedule'!$G$2:$G$500=$E$28),--('Week 6 Schedule'!$I$2:$I$500=$A29),--('Week 6 Schedule'!$J$2:$J$500>'Week 6 Schedule'!$H$2:$H$500))) | F29: =(SUMPRODUCT(--('Week 1 Schedule'!$B$2:$B$500=$A29),--('Week 1 Schedule'!$D$2:$D$500=$F$28),--('Week 1 Schedule'!$C$2:$C$500>'Week 1 Schedule'!$E$2:$E$500))+SUMPRODUCT(--('Week 1 Schedule'!$B$2:$B$500=$F$28),--('Week 1 Schedule'!$D$2:$D$500=$A29),--('Week 1 Schedule'!$E$2:$E$500>'Week 1 Schedule'!$C$2:$C$500)))+(SUMPRODUCT(--('Week 1 Schedule'!$G$2:$G$500=$A29),--('Week 1 Schedule'!$I$2:$I$500=$F$28),--('Week 1 Schedule'!$H$2:$H$500>'Week 1 Schedule'!$J$2:$J$500))+SUMPRODUCT(--('Week 1 Schedule'!$G$2:$G$500=$F$28),--('Week 1 Schedule'!$I$2:$I$500=$A29),--('Week 1 Schedule'!$J$2:$J$500>'Week 1 Schedule'!$H$2:$H$500)))+(SUMPRODUCT(--('Week 2 Schedule'!$B$2:$B$500=$A29),--('Week 2 Schedule'!$D$2:$D$500=$F$28),--('Week 2 Schedule'!$C$2:$C$500>'Week 2 Schedule'!$E$2:$E$500))+SUMPRODUCT(--('Week 2 Schedule'!$B$2:$B$500=$F$28),--('Week 2 Schedule'!$D$2:$D$500=$A29),--('Week 2 Schedule'!$E$2:$E$500>'Week 2 Schedule'!$C$2:$C$500)))+(SUMPRODUCT(--('Week 2 Schedule'!$G$2:$G$500=$A29),--('Week 2 Schedule'!$I$2:$I$500=$F$28),--('Week 2 Schedule'!$H$2:$H$500>'Week 2 Schedule'!$J$2:$J$500))+SUMPRODUCT(--('Week 2 Schedule'!$G$2:$G$500=$F$28),--('Week 2 Schedule'!$I$2:$I$500=$A29),--('Week 2 Schedule'!$J$2:$J$500>'Week 2 Schedule'!$H$2:$H$500)))+(SUMPRODUCT(--('Week 3 Schedule'!$B$2:$B$500=$A29),--('Week 3 Schedule'!$D$2:$D$500=$F$28),--('Week 3 Schedule'!$C$2:$C$500>'Week 3 Schedule'!$E$2:$E$500))+SUMPRODUCT(--('Week 3 Schedule'!$B$2:$B$500=$F$28),--('Week 3 Schedule'!$D$2:$D$500=$A29),--('Week 3 Schedule'!$E$2:$E$500>'Week 3 Schedule'!$C$2:$C$500)))+(SUMPRODUCT(--('Week 3 Schedule'!$G$2:$G$500=$A29),--('Week 3 Schedule'!$I$2:$I$500=$F$28),--('Week 3 Schedule'!$H$2:$H$500>'Week 3 Schedule'!$J$2:$J$500))+SUMPRODUCT(--('Week 3 Schedule'!$G$2:$G$500=$F$28),--('Week 3 Schedule'!$I$2:$I$500=$A29),--('Week 3 Schedule'!$J$2:$J$500>'Week 3 Schedule'!$H$2:$H$500)))+(SUMPRODUCT(--('Week 4 Schedule'!$B$2:$B$500=$A29),--('Week 4 Schedule'!$D$2:$D$500=$F$28),--('Week 4 Schedule'!$C$2:$C$500>'Week 4 Schedule'!$E$2:$E$500))+SUMPRODUCT(--('Week 4 Schedule'!$B$2:$B$500=$F$28),--('Week 4 Schedule'!$D$2:$D$500=$A29),--('Week 4 Schedule'!$E$2:$E$500>'Week 4 Schedule'!$C$2:$C$500)))+(SUMPRODUCT(--('Week 4 Schedule'!$G$2:$G$500=$A29),--('Week 4 Schedule'!$I$2:$I$500=$F$28),--('Week 4 Schedule'!$H$2:$H$500>'Week 4 Schedule'!$J$2:$J$500))+SUMPRODUCT(--('Week 4 Schedule'!$G$2:$G$500=$F$28),--('Week 4 Schedule'!$I$2:$I$500=$A29),--('Week 4 Schedule'!$J$2:$J$500>'Week 4 Schedule'!$H$2:$H$500)))+(SUMPRODUCT(--('Week 5 Schedule'!$B$2:$B$500=$A29),--('Week 5 Schedule'!$D$2:$D$500=$F$28),--('Week 5 Schedule'!$C$2:$C$500>'Week 5 Schedule'!$E$2:$E$500))+SUMPRODUCT(--('Week 5 Schedule'!$B$2:$B$500=$F$28),--('Week 5 Schedule'!$D$2:$D$500=$A29),--('Week 5 Schedule'!$E$2:$E$500>'Week 5 Schedule'!$C$2:$C$500)))+(SUMPRODUCT(--('Week 5 Schedule'!$G$2:$G$500=$A29),--('Week 5 Schedule'!$I$2:$I$500=$F$28),--('Week 5 Schedule'!$H$2:$H$500>'Week 5 Schedule'!$J$2:$J$500))+SUMPRODUCT(--('Week 5 Schedule'!$G$2:$G$500=$F$28),--('Week 5 Schedule'!$I$2:$I$500=$A29),--('Week 5 Schedule'!$J$2:$J$500>'Week 5 Schedule'!$H$2:$H$500)))+(SUMPRODUCT(--('Week 6 Schedule'!$B$2:$B$500=$A29),--('Week 6 Schedule'!$D$2:$D$500=$F$28),--('Week 6 Schedule'!$C$2:$C$500>'Week 6 Schedule'!$E$2:$E$500))+SUMPRODUCT(--('Week 6 Schedule'!$B$2:$B$500=$F$28),--('Week 6 Schedule'!$D$2:$D$500=$A29),--('Week 6 Schedule'!$E$2:$E$500>'Week 6 Schedule'!$C$2:$C$500)))+(SUMPRODUCT(--('Week 6 Schedule'!$G$2:$G$500=$A29),--('Week 6 Schedule'!$I$2:$I$500=$F$28),--('Week 6 Schedule'!$H$2:$H$500>'Week 6 Schedule'!$J$2:$J$500))+SUMPRODUCT(--('Week 6 Schedule'!$G$2:$G$500=$F$28),--('Week 6 Schedule'!$I$2:$I$500=$A29),--('Week 6 Schedule'!$J$2:$J$500>'Week 6 Schedule'!$H$2:$H$500))) | G29: =(SUMPRODUCT(--('Week 1 Schedule'!$B$2:$B$500=$A29),--('Week 1 Schedule'!$D$2:$D$500=$G$28),--('Week 1 Schedule'!$C$2:$C$500>'Week 1 Schedule'!$E$2:$E$500))+SUMPRODUCT(--('Week 1 Schedule'!$B$2:$B$500=$G$28),--('Week 1 Schedule'!$D$2:$D$500=$A29),--('Week 1 Schedule'!$E$2:$E$500>'Week 1 Schedule'!$C$2:$C$500)))+(SUMPRODUCT(--('Week 1 Schedule'!$G$2:$G$500=$A29),--('Week 1 Schedule'!$I$2:$I$500=$G$28),--('Week 1 Schedule'!$H$2:$H$500>'Week 1 Schedule'!$J$2:$J$500))+SUMPRODUCT(--('Week 1 Schedule'!$G$2:$G$500=$G$28),--('Week 1 Schedule'!$I$2:$I$500=$A29),--('Week 1 Schedule'!$J$2:$J$500>'Week 1 Schedule'!$H$2:$H$500)))+(SUMPRODUCT(--('Week 2 Schedule'!$B$2:$B$500=$A29),--('Week 2 Schedule'!$D$2:$D$500=$G$28),--('Week 2 Schedule'!$C$2:$C$500>'Week 2 Schedule'!$E$2:$E$500))+SUMPRODUCT(--('Week 2 Schedule'!$B$2:$B$500=$G$28),--('Week 2 Schedule'!$D$2:$D$500=$A29),--('Week 2 Schedule'!$E$2:$E$500>'Week 2 Schedule'!$C$2:$C$500)))+(SUMPRODUCT(--('Week 2 Schedule'!$G$2:$G$500=$A29),--('Week 2 Schedule'!$I$2:$I$500=$G$28),--('Week 2 Schedule'!$H$2:$H$500>'Week 2 Schedule'!$J$2:$J$500))+SUMPRODUCT(--('Week 2 Schedule'!$G$2:$G$500=$G$28),--('Week 2 Schedule'!$I$2:$I$500=$A29),--('Week 2 Schedule'!$J$2:$J$500>'Week 2 Schedule'!$H$2:$H$500)))+(SUMPRODUCT(--('Week 3 Schedule'!$B$2:$B$500=$A29),--('Week 3 Schedule'!$D$2:$D$500=$G$28),--('Week 3 Schedule'!$C$2:$C$500>'Week 3 Schedule'!$E$2:$E$500))+SUMPRODUCT(--('Week 3 Schedule'!$B$2:$B$500=$G$28),--('Week 3 Schedule'!$D$2:$D$500=$A29),--('Week 3 Schedule'!$E$2:$E$500>'Week 3 Schedule'!$C$2:$C$500)))+(SUMPRODUCT(--('Week 3 Schedule'!$G$2:$G$500=$A29),--('Week 3 Schedule'!$I$2:$I$500=$G$28),--('Week 3 Schedule'!$H$2:$H$500>'Week 3 Schedule'!$J$2:$J$500))+SUMPRODUCT(--('Week 3 Schedule'!$G$2:$G$500=$G$28),--('Week 3 Schedule'!$I$2:$I$500=$A29),--('Week 3 Schedule'!$J$2:$J$500>'Week 3 Schedule'!$H$2:$H$500)))+(SUMPRODUCT(--('Week 4 Schedule'!$B$2:$B$500=$A29),--('Week 4 Schedule'!$D$2:$D$500=$G$28),--('Week 4 Schedule'!$C$2:$C$500>'Week 4 Schedule'!$E$2:$E$500))+SUMPRODUCT(--('Week 4 Schedule'!$B$2:$B$500=$G$28),--('Week 4 Schedule'!$D$2:$D$500=$A29),--('Week 4 Schedule'!$E$2:$E$500>'Week 4 Schedule'!$C$2:$C$500)))+(SUMPRODUCT(--('Week 4 Schedule'!$G$2:$G$500=$A29),--('Week 4 Schedule'!$I$2:$I$500=$G$28),--('Week 4 Schedule'!$H$2:$H$500>'Week 4 Schedule'!$J$2:$J$500))+SUMPRODUCT(--('Week 4 Schedule'!$G$2:$G$500=$G$28),--('Week 4 Schedule'!$I$2:$I$500=$A29),--('Week 4 Schedule'!$J$2:$J$500>'Week 4 Schedule'!$H$2:$H$500)))+(SUMPRODUCT(--('Week 5 Schedule'!$B$2:$B$500=$A29),--('Week 5 Schedule'!$D$2:$D$500=$G$28),--('Week 5 Schedule'!$C$2:$C$500>'Week 5 Schedule'!$E$2:$E$500))+SUMPRODUCT(--('Week 5 Schedule'!$B$2:$B$500=$G$28),--('Week 5 Schedule'!$D$2:$D$500=$A29),--('Week 5 Schedule'!$E$2:$E$500>'Week 5 Schedule'!$C$2:$C$500)))+(SUMPRODUCT(--('Week 5 Schedule'!$G$2:$G$500=$A29),--('Week 5 Schedule'!$I$2:$I$500=$G$28),--('Week 5 Schedule'!$H$2:$H$500>'Week 5 Schedule'!$J$2:$J$500))+SUMPRODUCT(--('Week 5 Schedule'!$G$2:$G$500=$G$28),--('Week 5 Schedule'!$I$2:$I$500=$A29),--('Week 5 Schedule'!$J$2:$J$500>'Week 5 Schedule'!$H$2:$H$500)))+(SUMPRODUCT(--('Week 6 Schedule'!$B$2:$B$500=$A29),--('Week 6 Schedule'!$D$2:$D$500=$G$28),--('Week 6 Schedule'!$C$2:$C$500>'Week 6 Schedule'!$E$2:$E$500))+SUMPRODUCT(--('Week 6 Schedule'!$B$2:$B$500=$G$28),--('Week 6 Schedule'!$D$2:$D$500=$A29),--('Week 6 Schedule'!$E$2:$E$500>'Week 6 Schedule'!$C$2:$C$500)))+(SUMPRODUCT(--('Week 6 Schedule'!$G$2:$G$500=$A29),--('Week 6 Schedule'!$I$2:$I$500=$G$28),--('Week 6 Schedule'!$H$2:$H$500>'Week 6 Schedule'!$J$2:$J$500))+SUMPRODUCT(--('Week 6 Schedule'!$G$2:$G$500=$G$28),--('Week 6 Schedule'!$I$2:$I$500=$A29),--('Week 6 Schedule'!$J$2:$J$500>'Week 6 Schedule'!$H$2:$H$500))) | H29: =(SUMPRODUCT(--('Week 1 Schedule'!$B$2:$B$500=$A29),--('Week 1 Schedule'!$D$2:$D$500=$H$28),--('Week 1 Schedule'!$C$2:$C$500>'Week 1 Schedule'!$E$2:$E$500))+SUMPRODUCT(--('Week 1 Schedule'!$B$2:$B$500=$H$28),--('Week 1 Schedule'!$D$2:$D$500=$A29),--('Week 1 Schedule'!$E$2:$E$500>'Week 1 Schedule'!$C$2:$C$500)))+(SUMPRODUCT(--('Week 1 Schedule'!$G$2:$G$500=$A29),--('Week 1 Schedule'!$I$2:$I$500=$H$28),--('Week 1 Schedule'!$H$2:$H$500>'Week 1 Schedule'!$J$2:$J$500))+SUMPRODUCT(--('Week 1 Schedule'!$G$2:$G$500=$H$28),--('Week 1 Schedule'!$I$2:$I$500=$A29),--('Week 1 Schedule'!$J$2:$J$500>'Week 1 Schedule'!$H$2:$H$500)))+(SUMPRODUCT(--('Week 2 Schedule'!$B$2:$B$500=$A29),--('Week 2 Schedule'!$D$2:$D$500=$H$28),--('Week 2 Schedule'!$C$2:$C$500>'Week 2 Schedule'!$E$2:$E$500))+SUMPRODUCT(--('Week 2 Schedule'!$B$2:$B$500=$H$28),--('Week 2 Schedule'!$D$2:$D$500=$A29),--('Week 2 Schedule'!$E$2:$E$500>'Week 2 Schedule'!$C$2:$C$500)))+(SUMPRODUCT(--('Week 2 Schedule'!$G$2:$G$500=$A29),--('Week 2 Schedule'!$I$2:$I$500=$H$28),--('Week 2 Schedule'!$H$2:$H$500>'Week 2 Schedule'!$J$2:$J$500))+SUMPRODUCT(--('Week 2 Schedule'!$G$2:$G$500=$H$28),--('Week 2 Schedule'!$I$2:$I$500=$A29),--('Week 2 Schedule'!$J$2:$J$500>'Week 2 Schedule'!$H$2:$H$500)))+(SUMPRODUCT(--('Week 3 Schedule'!$B$2:$B$500=$A29),--('Week 3 Schedule'!$D$2:$D$500=$H$28),--('Week 3 Schedule'!$C$2:$C$500>'Week 3 Schedule'!$E$2:$E$500))+SUMPRODUCT(--('Week 3 Schedule'!$B$2:$B$500=$H$28),--('Week 3 Schedule'!$D$2:$D$500=$A29),--('Week 3 Schedule'!$E$2:$E$500>'Week 3 Schedule'!$C$2:$C$500)))+(SUMPRODUCT(--('Week 3 Schedule'!$G$2:$G$500=$A29),--('Week 3 Schedule'!$I$2:$I$500=$H$28),--('Week 3 Schedule'!$H$2:$H$500>'Week 3 Schedule'!$J$2:$J$500))+SUMPRODUCT(--('Week 3 Schedule'!$G$2:$G$500=$H$28),--('Week 3 Schedule'!$I$2:$I$500=$A29),--('Week 3 Schedule'!$J$2:$J$500>'Week 3 Schedule'!$H$2:$H$500)))+(SUMPRODUCT(--('Week 4 Schedule'!$B$2:$B$500=$A29),--('Week 4 Schedule'!$D$2:$D$500=$H$28),--('Week 4 Schedule'!$C$2:$C$500>'Week 4 Schedule'!$E$2:$E$500))+SUMPRODUCT(--('Week 4 Schedule'!$B$2:$B$500=$H$28),--('Week 4 Schedule'!$D$2:$D$500=$A29),--('Week 4 Schedule'!$E$2:$E$500>'Week 4 Schedule'!$C$2:$C$500)))+(SUMPRODUCT(--('Week 4 Schedule'!$G$2:$G$500=$A29),--('Week 4 Schedule'!$I$2:$I$500=$H$28),--('Week 4 Schedule'!$H$2:$H$500>'Week 4 Schedule'!$J$2:$J$500))+SUMPRODUCT(--('Week 4 Schedule'!$G$2:$G$500=$H$28),--('Week 4 Schedule'!$I$2:$I$500=$A29),--('Week 4 Schedule'!$J$2:$J$500>'Week 4 Schedule'!$H$2:$H$500)))+(SUMPRODUCT(--('Week 5 Schedule'!$B$2:$B$500=$A29),--('Week 5 Schedule'!$D$2:$D$500=$H$28),--('Week 5 Schedule'!$C$2:$C$500>'Week 5 Schedule'!$E$2:$E$500))+SUMPRODUCT(--('Week 5 Schedule'!$B$2:$B$500=$H$28),--('Week 5 Schedule'!$D$2:$D$500=$A29),--('Week 5 Schedule'!$E$2:$E$500>'Week 5 Schedule'!$C$2:$C$500)))+(SUMPRODUCT(--('Week 5 Schedule'!$G$2:$G$500=$A29),--('Week 5 Schedule'!$I$2:$I$500=$H$28),--('Week 5 Schedule'!$H$2:$H$500>'Week 5 Schedule'!$J$2:$J$500))+SUMPRODUCT(--('Week 5 Schedule'!$G$2:$G$500=$H$28),--('Week 5 Schedule'!$I$2:$I$500=$A29),--('Week 5 Schedule'!$J$2:$J$500>'Week 5 Schedule'!$H$2:$H$500)))+(SUMPRODUCT(--('Week 6 Schedule'!$B$2:$B$500=$A29),--('Week 6 Schedule'!$D$2:$D$500=$H$28),--('Week 6 Schedule'!$C$2:$C$500>'Week 6 Schedule'!$E$2:$E$500))+SUMPRODUCT(--('Week 6 Schedule'!$B$2:$B$500=$H$28),--('Week 6 Schedule'!$D$2:$D$500=$A29),--('Week 6 Schedule'!$E$2:$E$500>'Week 6 Schedule'!$C$2:$C$500)))+(SUMPRODUCT(--('Week 6 Schedule'!$G$2:$G$500=$A29),--('Week 6 Schedule'!$I$2:$I$500=$H$28),--('Week 6 Schedule'!$H$2:$H$500>'Week 6 Schedule'!$J$2:$J$500))+SUMPRODUCT(--('Week 6 Schedule'!$G$2:$G$500=$H$28),--('Week 6 Schedule'!$I$2:$I$500=$A29),--('Week 6 Schedule'!$J$2:$J$500>'Week 6 Schedule'!$H$2:$H$500))) | I29: =(SUMPRODUCT(--('Week 1 Schedule'!$B$2:$B$500=$A29),--('Week 1 Schedule'!$D$2:$D$500=$I$28),--('Week 1 Schedule'!$C$2:$C$500>'Week 1 Schedule'!$E$2:$E$500))+SUMPRODUCT(--('Week 1 Schedule'!$B$2:$B$500=$I$28),--('Week 1 Schedule'!$D$2:$D$500=$A29),--('Week 1 Schedule'!$E$2:$E$500>'Week 1 Schedule'!$C$2:$C$500)))+(SUMPRODUCT(--('Week 1 Schedule'!$G$2:$G$500=$A29),--('Week 1 Schedule'!$I$2:$I$500=$I$28),--('Week 1 Schedule'!$H$2:$H$500>'Week 1 Schedule'!$J$2:$J$500))+SUMPRODUCT(--('Week 1 Schedule'!$G$2:$G$500=$I$28),--('Week 1 Schedule'!$I$2:$I$500=$A29),--('Week 1 Schedule'!$J$2:$J$500>'Week 1 Schedule'!$H$2:$H$500)))+(SUMPRODUCT(--('Week 2 Schedule'!$B$2:$B$500=$A29),--('Week 2 Schedule'!$D$2:$D$500=$I$28),--('Week 2 Schedule'!$C$2:$C$500>'Week 2 Schedule'!$E$2:$E$500))+SUMPRODUCT(--('Week 2 Schedule'!$B$2:$B$500=$I$28),--('Week 2 Schedule'!$D$2:$D$500=$A29),--('Week 2 Schedule'!$E$2:$E$500>'Week 2 Schedule'!$C$2:$C$500)))+(SUMPRODUCT(--('Week 2 Schedule'!$G$2:$G$500=$A29),--('Week 2 Schedule'!$I$2:$I$500=$I$28),--('Week 2 Schedule'!$H$2:$H$500>'Week 2 Schedule'!$J$2:$J$500))+SUMPRODUCT(--('Week 2 Schedule'!$G$2:$G$500=$I$28),--('Week 2 Schedule'!$I$2:$I$500=$A29),--('Week 2 Schedule'!$J$2:$J$500>'Week 2 Schedule'!$H$2:$H$500)))+(SUMPRODUCT(--('Week 3 Schedule'!$B$2:$B$500=$A29),--('Week 3 Schedule'!$D$2:$D$500=$I$28),--('Week 3 Schedule'!$C$2:$C$500>'Week 3 Schedule'!$E$2:$E$500))+SUMPRODUCT(--('Week 3 Schedule'!$B$2:$B$500=$I$28),--('Week 3 Schedule'!$D$2:$D$500=$A29),--('Week 3 Schedule'!$E$2:$E$500>'Week 3 Schedule'!$C$2:$C$500)))+(SUMPRODUCT(--('Week 3 Schedule'!$G$2:$G$500=$A29),--('Week 3 Schedule'!$I$2:$I$500=$I$28),--('Week 3 Schedule'!$H$2:$H$500>'Week 3 Schedule'!$J$2:$J$500))+SUMPRODUCT(--('Week 3 Schedule'!$G$2:$G$500=$I$28),--('Week 3 Schedule'!$I$2:$I$500=$A29),--('Week 3 Schedule'!$J$2:$J$500>'Week 3 Schedule'!$H$2:$H$500)))+(SUMPRODUCT(--('Week 4 Schedule'!$B$2:$B$500=$A29),--('Week 4 Schedule'!$D$2:$D$500=$I$28),--('Week 4 Schedule'!$C$2:$C$500>'Week 4 Schedule'!$E$2:$E$500))+SUMPRODUCT(--('Week 4 Schedule'!$B$2:$B$500=$I$28),--('Week 4 Schedule'!$D$2:$D$500=$A29),--('Week 4 Schedule'!$E$2:$E$500>'Week 4 Schedule'!$C$2:$C$500)))+(SUMPRODUCT(--('Week 4 Schedule'!$G$2:$G$500=$A29),--('Week 4 Schedule'!$I$2:$I$500=$I$28),--('Week 4 Schedule'!$H$2:$H$500>'Week 4 Schedule'!$J$2:$J$500))+SUMPRODUCT(--('Week 4 Schedule'!$G$2:$G$500=$I$28),--('Week 4 Schedule'!$I$2:$I$500=$A29),--('Week 4 Schedule'!$J$2:$J$500>'Week 4 Schedule'!$H$2:$H$500)))+(SUMPRODUCT(--('Week 5 Schedule'!$B$2:$B$500=$A29),--('Week 5 Schedule'!$D$2:$D$500=$I$28),--('Week 5 Schedule'!$C$2:$C$500>'Week 5 Schedule'!$E$2:$E$500))+SUMPRODUCT(--('Week 5 Schedule'!$B$2:$B$500=$I$28),--('Week 5 Schedule'!$D$2:$D$500=$A29),--('Week 5 Schedule'!$E$2:$E$500>'Week 5 Schedule'!$C$2:$C$500)))+(SUMPRODUCT(--('Week 5 Schedule'!$G$2:$G$500=$A29),--('Week 5 Schedule'!$I$2:$I$500=$I$28),--('Week 5 Schedule'!$H$2:$H$500>'Week 5 Schedule'!$J$2:$J$500))+SUMPRODUCT(--('Week 5 Schedule'!$G$2:$G$500=$I$28),--('Week 5 Schedule'!$I$2:$I$500=$A29),--('Week 5 Schedule'!$J$2:$J$500>'Week 5 Schedule'!$H$2:$H$500)))+(SUMPRODUCT(--('Week 6 Schedule'!$B$2:$B$500=$A29),--('Week 6 Schedule'!$D$2:$D$500=$I$28),--('Week 6 Schedule'!$C$2:$C$500>'Week 6 Schedule'!$E$2:$E$500))+SUMPRODUCT(--('Week 6 Schedule'!$B$2:$B$500=$I$28),--('Week 6 Schedule'!$D$2:$D$500=$A29),--('Week 6 Schedule'!$E$2:$E$500>'Week 6 Schedule'!$C$2:$C$500)))+(SUMPRODUCT(--('Week 6 Schedule'!$G$2:$G$500=$A29),--('Week 6 Schedule'!$I$2:$I$500=$I$28),--('Week 6 Schedule'!$H$2:$H$500>'Week 6 Schedule'!$J$2:$J$500))+SUMPRODUCT(--('Week 6 Schedule'!$G$2:$G$500=$I$28),--('Week 6 Schedule'!$I$2:$I$500=$A29),--('Week 6 Schedule'!$J$2:$J$500>'Week 6 Schedule'!$H$2:$H$500)))
A30: Team 2 | B30: =(SUMPRODUCT(--('Week 1 Schedule'!$B$2:$B$500=$A30),--('Week 1 Schedule'!$D$2:$D$500=$B$28),--('Week 1 Schedule'!$C$2:$C$500>'Week 1 Schedule'!$E$2:$E$500))+SUMPRODUCT(--('Week 1 Schedule'!$B$2:$B$500=$B$28),--('Week 1 Schedule'!$D$2:$D$500=$A30),--('Week 1 Schedule'!$E$2:$E$500>'Week 1 Schedule'!$C$2:$C$500)))+(SUMPRODUCT(--('Week 1 Schedule'!$G$2:$G$500=$A30),--('Week 1 Schedule'!$I$2:$I$500=$B$28),--('Week 1 Schedule'!$H$2:$H$500>'Week 1 Schedule'!$J$2:$J$500))+SUMPRODUCT(--('Week 1 Schedule'!$G$2:$G$500=$B$28),--('Week 1 Schedule'!$I$2:$I$500=$A30),--('Week 1 Schedule'!$J$2:$J$500>'Week 1 Schedule'!$H$2:$H$500)))+(SUMPRODUCT(--('Week 2 Schedule'!$B$2:$B$500=$A30),--('Week 2 Schedule'!$D$2:$D$500=$B$28),--('Week 2 Schedule'!$C$2:$C$500>'Week 2 Schedule'!$E$2:$E$500))+SUMPRODUCT(--('Week 2 Schedule'!$B$2:$B$500=$B$28),--('Week 2 Schedule'!$D$2:$D$500=$A30),--('Week 2 Schedule'!$E$2:$E$500>'Week 2 Schedule'!$C$2:$C$500)))+(SUMPRODUCT(--('Week 2 Schedule'!$G$2:$G$500=$A30),--('Week 2 Schedule'!$I$2:$I$500=$B$28),--('Week 2 Schedule'!$H$2:$H$500>'Week 2 Schedule'!$J$2:$J$500))+SUMPRODUCT(--('Week 2 Schedule'!$G$2:$G$500=$B$28),--('Week 2 Schedule'!$I$2:$I$500=$A30),--('Week 2 Schedule'!$J$2:$J$500>'Week 2 Schedule'!$H$2:$H$500)))+(SUMPRODUCT(--('Week 3 Schedule'!$B$2:$B$500=$A30),--('Week 3 Schedule'!$D$2:$D$500=$B$28),--('Week 3 Schedule'!$C$2:$C$500>'Week 3 Schedule'!$E$2:$E$500))+SUMPRODUCT(--('Week 3 Schedule'!$B$2:$B$500=$B$28),--('Week 3 Schedule'!$D$2:$D$500=$A30),--('Week 3 Schedule'!$E$2:$E$500>'Week 3 Schedule'!$C$2:$C$500)))+(SUMPRODUCT(--('Week 3 Schedule'!$G$2:$G$500=$A30),--('Week 3 Schedule'!$I$2:$I$500=$B$28),--('Week 3 Schedule'!$H$2:$H$500>'Week 3 Schedule'!$J$2:$J$500))+SUMPRODUCT(--('Week 3 Schedule'!$G$2:$G$500=$B$28),--('Week 3 Schedule'!$I$2:$I$500=$A30),--('Week 3 Schedule'!$J$2:$J$500>'Week 3 Schedule'!$H$2:$H$500)))+(SUMPRODUCT(--('Week 4 Schedule'!$B$2:$B$500=$A30),--('Week 4 Schedule'!$D$2:$D$500=$B$28),--('Week 4 Schedule'!$C$2:$C$500>'Week 4 Schedule'!$E$2:$E$500))+SUMPRODUCT(--('Week 4 Schedule'!$B$2:$B$500=$B$28),--('Week 4 Schedule'!$D$2:$D$500=$A30),--('Week 4 Schedule'!$E$2:$E$500>'Week 4 Schedule'!$C$2:$C$500)))+(SUMPRODUCT(--('Week 4 Schedule'!$G$2:$G$500=$A30),--('Week 4 Schedule'!$I$2:$I$500=$B$28),--('Week 4 Schedule'!$H$2:$H$500>'Week 4 Schedule'!$J$2:$J$500))+SUMPRODUCT(--('Week 4 Schedule'!$G$2:$G$500=$B$28),--('Week 4 Schedule'!$I$2:$I$500=$A30),--('Week 4 Schedule'!$J$2:$J$500>'Week 4 Schedule'!$H$2:$H$500)))+(SUMPRODUCT(--('Week 5 Schedule'!$B$2:$B$500=$A30),--('Week 5 Schedule'!$D$2:$D$500=$B$28),--('Week 5 Schedule'!$C$2:$C$500>'Week 5 Schedule'!$E$2:$E$500))+SUMPRODUCT(--('Week 5 Schedule'!$B$2:$B$500=$B$28),--('Week 5 Schedule'!$D$2:$D$500=$A30),--('Week 5 Schedule'!$E$2:$E$500>'Week 5 Schedule'!$C$2:$C$500)))+(SUMPRODUCT(--('Week 5 Schedule'!$G$2:$G$500=$A30),--('Week 5 Schedule'!$I$2:$I$500=$B$28),--('Week 5 Schedule'!$H$2:$H$500>'Week 5 Schedule'!$J$2:$J$500))+SUMPRODUCT(--('Week 5 Schedule'!$G$2:$G$500=$B$28),--('Week 5 Schedule'!$I$2:$I$500=$A30),--('Week 5 Schedule'!$J$2:$J$500>'Week 5 Schedule'!$H$2:$H$500)))+(SUMPRODUCT(--('Week 6 Schedule'!$B$2:$B$500=$A30),--('Week 6 Schedule'!$D$2:$D$500=$B$28),--('Week 6 Schedule'!$C$2:$C$500>'Week 6 Schedule'!$E$2:$E$500))+SUMPRODUCT(--('Week 6 Schedule'!$B$2:$B$500=$B$28),--('Week 6 Schedule'!$D$2:$D$500=$A30),--('Week 6 Schedule'!$E$2:$E$500>'Week 6 Schedule'!$C$2:$C$500)))+(SUMPRODUCT(--('Week 6 Schedule'!$G$2:$G$500=$A30),--('Week 6 Schedule'!$I$2:$I$500=$B$28),--('Week 6 Schedule'!$H$2:$H$500>'Week 6 Schedule'!$J$2:$J$500))+SUMPRODUCT(--('Week 6 Schedule'!$G$2:$G$500=$B$28),--('Week 6 Schedule'!$I$2:$I$500=$A30),--('Week 6 Schedule'!$J$2:$J$500>'Week 6 Schedule'!$H$2:$H$500))) | C30: — | D30: =(SUMPRODUCT(--('Week 1 Schedule'!$B$2:$B$500=$A30),--('Week 1 Schedule'!$D$2:$D$500=$D$28),--('Week 1 Schedule'!$C$2:$C$500>'Week 1 Schedule'!$E$2:$E$500))+SUMPRODUCT(--('Week 1 Schedule'!$B$2:$B$500=$D$28),--('Week 1 Schedule'!$D$2:$D$500=$A30),--('Week 1 Schedule'!$E$2:$E$500>'Week 1 Schedule'!$C$2:$C$500)))+(SUMPRODUCT(--('Week 1 Schedule'!$G$2:$G$500=$A30),--('Week 1 Schedule'!$I$2:$I$500=$D$28),--('Week 1 Schedule'!$H$2:$H$500>'Week 1 Schedule'!$J$2:$J$500))+SUMPRODUCT(--('Week 1 Schedule'!$G$2:$G$500=$D$28),--('Week 1 Schedule'!$I$2:$I$500=$A30),--('Week 1 Schedule'!$J$2:$J$500>'Week 1 Schedule'!$H$2:$H$500)))+(SUMPRODUCT(--('Week 2 Schedule'!$B$2:$B$500=$A30),--('Week 2 Schedule'!$D$2:$D$500=$D$28),--('Week 2 Schedule'!$C$2:$C$500>'Week 2 Schedule'!$E$2:$E$500))+SUMPRODUCT(--('Week 2 Schedule'!$B$2:$B$500=$D$28),--('Week 2 Schedule'!$D$2:$D$500=$A30),--('Week 2 Schedule'!$E$2:$E$500>'Week 2 Schedule'!$C$2:$C$500)))+(SUMPRODUCT(--('Week 2 Schedule'!$G$2:$G$500=$A30),--('Week 2 Schedule'!$I$2:$I$500=$D$28),--('Week 2 Schedule'!$H$2:$H$500>'Week 2 Schedule'!$J$2:$J$500))+SUMPRODUCT(--('Week 2 Schedule'!$G$2:$G$500=$D$28),--('Week 2 Schedule'!$I$2:$I$500=$A30),--('Week 2 Schedule'!$J$2:$J$500>'Week 2 Schedule'!$H$2:$H$500)))+(SUMPRODUCT(--('Week 3 Schedule'!$B$2:$B$500=$A30),--('Week 3 Schedule'!$D$2:$D$500=$D$28),--('Week 3 Schedule'!$C$2:$C$500>'Week 3 Schedule'!$E$2:$E$500))+SUMPRODUCT(--('Week 3 Schedule'!$B$2:$B$500=$D$28),--('Week 3 Schedule'!$D$2:$D$500=$A30),--('Week 3 Schedule'!$E$2:$E$500>'Week 3 Schedule'!$C$2:$C$500)))+(SUMPRODUCT(--('Week 3 Schedule'!$G$2:$G$500=$A30),--('Week 3 Schedule'!$I$2:$I$500=$D$28),--('Week 3 Schedule'!$H$2:$H$500>'Week 3 Schedule'!$J$2:$J$500))+SUMPRODUCT(--('Week 3 Schedule'!$G$2:$G$500=$D$28),--('Week 3 Schedule'!$I$2:$I$500=$A30),--('Week 3 Schedule'!$J$2:$J$500>'Week 3 Schedule'!$H$2:$H$500)))+(SUMPRODUCT(--('Week 4 Schedule'!$B$2:$B$500=$A30),--('Week 4 Schedule'!$D$2:$D$500=$D$28),--('Week 4 Schedule'!$C$2:$C$500>'Week 4 Schedule'!$E$2:$E$500))+SUMPRODUCT(--('Week 4 Schedule'!$B$2:$B$500=$D$28),--('Week 4 Schedule'!$D$2:$D$500=$A30),--('Week 4 Schedule'!$E$2:$E$500>'Week 4 Schedule'!$C$2:$C$500)))+(SUMPRODUCT(--('Week 4 Schedule'!$G$2:$G$500=$A30),--('Week 4 Schedule'!$I$2:$I$500=$D$28),--('Week 4 Schedule'!$H$2:$H$500>'Week 4 Schedule'!$J$2:$J$500))+SUMPRODUCT(--('Week 4 Schedule'!$G$2:$G$500=$D$28),--('Week 4 Schedule'!$I$2:$I$500=$A30),--('Week 4 Schedule'!$J$2:$J$500>'Week 4 Schedule'!$H$2:$H$500)))+(SUMPRODUCT(--('Week 5 Schedule'!$B$2:$B$500=$A30),--('Week 5 Schedule'!$D$2:$D$500=$D$28),--('Week 5 Schedule'!$C$2:$C$500>'Week 5 Schedule'!$E$2:$E$500))+SUMPRODUCT(--('Week 5 Schedule'!$B$2:$B$500=$D$28),--('Week 5 Schedule'!$D$2:$D$500=$A30),--('Week 5 Schedule'!$E$2:$E$500>'Week 5 Schedule'!$C$2:$C$500)))+(SUMPRODUCT(--('Week 5 Schedule'!$G$2:$G$500=$A30),--('Week 5 Schedule'!$I$2:$I$500=$D$28),--('Week 5 Schedule'!$H$2:$H$500>'Week 5 Schedule'!$J$2:$J$500))+SUMPRODUCT(--('Week 5 Schedule'!$G$2:$G$500=$D$28),--('Week 5 Schedule'!$I$2:$I$500=$A30),--('Week 5 Schedule'!$J$2:$J$500>'Week 5 Schedule'!$H$2:$H$500)))+(SUMPRODUCT(--('Week 6 Schedule'!$B$2:$B$500=$A30),--('Week 6 Schedule'!$D$2:$D$500=$D$28),--('Week 6 Schedule'!$C$2:$C$500>'Week 6 Schedule'!$E$2:$E$500))+SUMPRODUCT(--('Week 6 Schedule'!$B$2:$B$500=$D$28),--('Week 6 Schedule'!$D$2:$D$500=$A30),--('Week 6 Schedule'!$E$2:$E$500>'Week 6 Schedule'!$C$2:$C$500)))+(SUMPRODUCT(--('Week 6 Schedule'!$G$2:$G$500=$A30),--('Week 6 Schedule'!$I$2:$I$500=$D$28),--('Week 6 Schedule'!$H$2:$H$500>'Week 6 Schedule'!$J$2:$J$500))+SUMPRODUCT(--('Week 6 Schedule'!$G$2:$G$500=$D$28),--('Week 6 Schedule'!$I$2:$I$500=$A30),--('Week 6 Schedule'!$J$2:$J$500>'Week 6 Schedule'!$H$2:$H$500))) | E30: =(SUMPRODUCT(--('Week 1 Schedule'!$B$2:$B$500=$A30),--('Week 1 Schedule'!$D$2:$D$500=$E$28),--('Week 1 Schedule'!$C$2:$C$500>'Week 1 Schedule'!$E$2:$E$500))+SUMPRODUCT(--('Week 1 Schedule'!$B$2:$B$500=$E$28),--('Week 1 Schedule'!$D$2:$D$500=$A30),--('Week 1 Schedule'!$E$2:$E$500>'Week 1 Schedule'!$C$2:$C$500)))+(SUMPRODUCT(--('Week 1 Schedule'!$G$2:$G$500=$A30),--('Week 1 Schedule'!$I$2:$I$500=$E$28),--('Week 1 Schedule'!$H$2:$H$500>'Week 1 Schedule'!$J$2:$J$500))+SUMPRODUCT(--('Week 1 Schedule'!$G$2:$G$500=$E$28),--('Week 1 Schedule'!$I$2:$I$500=$A30),--('Week 1 Schedule'!$J$2:$J$500>'Week 1 Schedule'!$H$2:$H$500)))+(SUMPRODUCT(--('Week 2 Schedule'!$B$2:$B$500=$A30),--('Week 2 Schedule'!$D$2:$D$500=$E$28),--('Week 2 Schedule'!$C$2:$C$500>'Week 2 Schedule'!$E$2:$E$500))+SUMPRODUCT(--('Week 2 Schedule'!$B$2:$B$500=$E$28),--('Week 2 Schedule'!$D$2:$D$500=$A30),--('Week 2 Schedule'!$E$2:$E$500>'Week 2 Schedule'!$C$2:$C$500)))+(SUMPRODUCT(--('Week 2 Schedule'!$G$2:$G$500=$A30),--('Week 2 Schedule'!$I$2:$I$500=$E$28),--('Week 2 Schedule'!$H$2:$H$500>'Week 2 Schedule'!$J$2:$J$500))+SUMPRODUCT(--('Week 2 Schedule'!$G$2:$G$500=$E$28),--('Week 2 Schedule'!$I$2:$I$500=$A30),--('Week 2 Schedule'!$J$2:$J$500>'Week 2 Schedule'!$H$2:$H$500)))+(SUMPRODUCT(--('Week 3 Schedule'!$B$2:$B$500=$A30),--('Week 3 Schedule'!$D$2:$D$500=$E$28),--('Week 3 Schedule'!$C$2:$C$500>'Week 3 Schedule'!$E$2:$E$500))+SUMPRODUCT(--('Week 3 Schedule'!$B$2:$B$500=$E$28),--('Week 3 Schedule'!$D$2:$D$500=$A30),--('Week 3 Schedule'!$E$2:$E$500>'Week 3 Schedule'!$C$2:$C$500)))+(SUMPRODUCT(--('Week 3 Schedule'!$G$2:$G$500=$A30),--('Week 3 Schedule'!$I$2:$I$500=$E$28),--('Week 3 Schedule'!$H$2:$H$500>'Week 3 Schedule'!$J$2:$J$500))+SUMPRODUCT(--('Week 3 Schedule'!$G$2:$G$500=$E$28),--('Week 3 Schedule'!$I$2:$I$500=$A30),--('Week 3 Schedule'!$J$2:$J$500>'Week 3 Schedule'!$H$2:$H$500)))+(SUMPRODUCT(--('Week 4 Schedule'!$B$2:$B$500=$A30),--('Week 4 Schedule'!$D$2:$D$500=$E$28),--('Week 4 Schedule'!$C$2:$C$500>'Week 4 Schedule'!$E$2:$E$500))+SUMPRODUCT(--('Week 4 Schedule'!$B$2:$B$500=$E$28),--('Week 4 Schedule'!$D$2:$D$500=$A30),--('Week 4 Schedule'!$E$2:$E$500>'Week 4 Schedule'!$C$2:$C$500)))+(SUMPRODUCT(--('Week 4 Schedule'!$G$2:$G$500=$A30),--('Week 4 Schedule'!$I$2:$I$500=$E$28),--('Week 4 Schedule'!$H$2:$H$500>'Week 4 Schedule'!$J$2:$J$500))+SUMPRODUCT(--('Week 4 Schedule'!$G$2:$G$500=$E$28),--('Week 4 Schedule'!$I$2:$I$500=$A30),--('Week 4 Schedule'!$J$2:$J$500>'Week 4 Schedule'!$H$2:$H$500)))+(SUMPRODUCT(--('Week 5 Schedule'!$B$2:$B$500=$A30),--('Week 5 Schedule'!$D$2:$D$500=$E$28),--('Week 5 Schedule'!$C$2:$C$500>'Week 5 Schedule'!$E$2:$E$500))+SUMPRODUCT(--('Week 5 Schedule'!$B$2:$B$500=$E$28),--('Week 5 Schedule'!$D$2:$D$500=$A30),--('Week 5 Schedule'!$E$2:$E$500>'Week 5 Schedule'!$C$2:$C$500)))+(SUMPRODUCT(--('Week 5 Schedule'!$G$2:$G$500=$A30),--('Week 5 Schedule'!$I$2:$I$500=$E$28),--('Week 5 Schedule'!$H$2:$H$500>'Week 5 Schedule'!$J$2:$J$500))+SUMPRODUCT(--('Week 5 Schedule'!$G$2:$G$500=$E$28),--('Week 5 Schedule'!$I$2:$I$500=$A30),--('Week 5 Schedule'!$J$2:$J$500>'Week 5 Schedule'!$H$2:$H$500)))+(SUMPRODUCT(--('Week 6 Schedule'!$B$2:$B$500=$A30),--('Week 6 Schedule'!$D$2:$D$500=$E$28),--('Week 6 Schedule'!$C$2:$C$500>'Week 6 Schedule'!$E$2:$E$500))+SUMPRODUCT(--('Week 6 Schedule'!$B$2:$B$500=$E$28),--('Week 6 Schedule'!$D$2:$D$500=$A30),--('Week 6 Schedule'!$E$2:$E$500>'Week 6 Schedule'!$C$2:$C$500)))+(SUMPRODUCT(--('Week 6 Schedule'!$G$2:$G$500=$A30),--('Week 6 Schedule'!$I$2:$I$500=$E$28),--('Week 6 Schedule'!$H$2:$H$500>'Week 6 Schedule'!$J$2:$J$500))+SUMPRODUCT(--('Week 6 Schedule'!$G$2:$G$500=$E$28),--('Week 6 Schedule'!$I$2:$I$500=$A30),--('Week 6 Schedule'!$J$2:$J$500>'Week 6 Schedule'!$H$2:$H$500))) | F30: =(SUMPRODUCT(--('Week 1 Schedule'!$B$2:$B$500=$A30),--('Week 1 Schedule'!$D$2:$D$500=$F$28),--('Week 1 Schedule'!$C$2:$C$500>'Week 1 Schedule'!$E$2:$E$500))+SUMPRODUCT(--('Week 1 Schedule'!$B$2:$B$500=$F$28),--('Week 1 Schedule'!$D$2:$D$500=$A30),--('Week 1 Schedule'!$E$2:$E$500>'Week 1 Schedule'!$C$2:$C$500)))+(SUMPRODUCT(--('Week 1 Schedule'!$G$2:$G$500=$A30),--('Week 1 Schedule'!$I$2:$I$500=$F$28),--('Week 1 Schedule'!$H$2:$H$500>'Week 1 Schedule'!$J$2:$J$500))+SUMPRODUCT(--('Week 1 Schedule'!$G$2:$G$500=$F$28),--('Week 1 Schedule'!$I$2:$I$500=$A30),--('Week 1 Schedule'!$J$2:$J$500>'Week 1 Schedule'!$H$2:$H$500)))+(SUMPRODUCT(--('Week 2 Schedule'!$B$2:$B$500=$A30),--('Week 2 Schedule'!$D$2:$D$500=$F$28),--('Week 2 Schedule'!$C$2:$C$500>'Week 2 Schedule'!$E$2:$E$500))+SUMPRODUCT(--('Week 2 Schedule'!$B$2:$B$500=$F$28),--('Week 2 Schedule'!$D$2:$D$500=$A30),--('Week 2 Schedule'!$E$2:$E$500>'Week 2 Schedule'!$C$2:$C$500)))+(SUMPRODUCT(--('Week 2 Schedule'!$G$2:$G$500=$A30),--('Week 2 Schedule'!$I$2:$I$500=$F$28),--('Week 2 Schedule'!$H$2:$H$500>'Week 2 Schedule'!$J$2:$J$500))+SUMPRODUCT(--('Week 2 Schedule'!$G$2:$G$500=$F$28),--('Week 2 Schedule'!$I$2:$I$500=$A30),--('Week 2 Schedule'!$J$2:$J$500>'Week 2 Schedule'!$H$2:$H$500)))+(SUMPRODUCT(--('Week 3 Schedule'!$B$2:$B$500=$A30),--('Week 3 Schedule'!$D$2:$D$500=$F$28),--('Week 3 Schedule'!$C$2:$C$500>'Week 3 Schedule'!$E$2:$E$500))+SUMPRODUCT(--('Week 3 Schedule'!$B$2:$B$500=$F$28),--('Week 3 Schedule'!$D$2:$D$500=$A30),--('Week 3 Schedule'!$E$2:$E$500>'Week 3 Schedule'!$C$2:$C$500)))+(SUMPRODUCT(--('Week 3 Schedule'!$G$2:$G$500=$A30),--('Week 3 Schedule'!$I$2:$I$500=$F$28),--('Week 3 Schedule'!$H$2:$H$500>'Week 3 Schedule'!$J$2:$J$500))+SUMPRODUCT(--('Week 3 Schedule'!$G$2:$G$500=$F$28),--('Week 3 Schedule'!$I$2:$I$500=$A30),--('Week 3 Schedule'!$J$2:$J$500>'Week 3 Schedule'!$H$2:$H$500)))+(SUMPRODUCT(--('Week 4 Schedule'!$B$2:$B$500=$A30),--('Week 4 Schedule'!$D$2:$D$500=$F$28),--('Week 4 Schedule'!$C$2:$C$500>'Week 4 Schedule'!$E$2:$E$500))+SUMPRODUCT(--('Week 4 Schedule'!$B$2:$B$500=$F$28),--('Week 4 Schedule'!$D$2:$D$500=$A30),--('Week 4 Schedule'!$E$2:$E$500>'Week 4 Schedule'!$C$2:$C$500)))+(SUMPRODUCT(--('Week 4 Schedule'!$G$2:$G$500=$A30),--('Week 4 Schedule'!$I$2:$I$500=$F$28),--('Week 4 Schedule'!$H$2:$H$500>'Week 4 Schedule'!$J$2:$J$500))+SUMPRODUCT(--('Week 4 Schedule'!$G$2:$G$500=$F$28),--('Week 4 Schedule'!$I$2:$I$500=$A30),--('Week 4 Schedule'!$J$2:$J$500>'Week 4 Schedule'!$H$2:$H$500)))+(SUMPRODUCT(--('Week 5 Schedule'!$B$2:$B$500=$A30),--('Week 5 Schedule'!$D$2:$D$500=$F$28),--('Week 5 Schedule'!$C$2:$C$500>'Week 5 Schedule'!$E$2:$E$500))+SUMPRODUCT(--('Week 5 Schedule'!$B$2:$B$500=$F$28),--('Week 5 Schedule'!$D$2:$D$500=$A30),--('Week 5 Schedule'!$E$2:$E$500>'Week 5 Schedule'!$C$2:$C$500)))+(SUMPRODUCT(--('Week 5 Schedule'!$G$2:$G$500=$A30),--('Week 5 Schedule'!$I$2:$I$500=$F$28),--('Week 5 Schedule'!$H$2:$H$500>'Week 5 Schedule'!$J$2:$J$500))+SUMPRODUCT(--('Week 5 Schedule'!$G$2:$G$500=$F$28),--('Week 5 Schedule'!$I$2:$I$500=$A30),--('Week 5 Schedule'!$J$2:$J$500>'Week 5 Schedule'!$H$2:$H$500)))+(SUMPRODUCT(--('Week 6 Schedule'!$B$2:$B$500=$A30),--('Week 6 Schedule'!$D$2:$D$500=$F$28),--('Week 6 Schedule'!$C$2:$C$500>'Week 6 Schedule'!$E$2:$E$500))+SUMPRODUCT(--('Week 6 Schedule'!$B$2:$B$500=$F$28),--('Week 6 Schedule'!$D$2:$D$500=$A30),--('Week 6 Schedule'!$E$2:$E$500>'Week 6 Schedule'!$C$2:$C$500)))+(SUMPRODUCT(--('Week 6 Schedule'!$G$2:$G$500=$A30),--('Week 6 Schedule'!$I$2:$I$500=$F$28),--('Week 6 Schedule'!$H$2:$H$500>'Week 6 Schedule'!$J$2:$J$500))+SUMPRODUCT(--('Week 6 Schedule'!$G$2:$G$500=$F$28),--('Week 6 Schedule'!$I$2:$I$500=$A30),--('Week 6 Schedule'!$J$2:$J$500>'Week 6 Schedule'!$H$2:$H$500))) | G30: =(SUMPRODUCT(--('Week 1 Schedule'!$B$2:$B$500=$A30),--('Week 1 Schedule'!$D$2:$D$500=$G$28),--('Week 1 Schedule'!$C$2:$C$500>'Week 1 Schedule'!$E$2:$E$500))+SUMPRODUCT(--('Week 1 Schedule'!$B$2:$B$500=$G$28),--('Week 1 Schedule'!$D$2:$D$500=$A30),--('Week 1 Schedule'!$E$2:$E$500>'Week 1 Schedule'!$C$2:$C$500)))+(SUMPRODUCT(--('Week 1 Schedule'!$G$2:$G$500=$A30),--('Week 1 Schedule'!$I$2:$I$500=$G$28),--('Week 1 Schedule'!$H$2:$H$500>'Week 1 Schedule'!$J$2:$J$500))+SUMPRODUCT(--('Week 1 Schedule'!$G$2:$G$500=$G$28),--('Week 1 Schedule'!$I$2:$I$500=$A30),--('Week 1 Schedule'!$J$2:$J$500>'Week 1 Schedule'!$H$2:$H$500)))+(SUMPRODUCT(--('Week 2 Schedule'!$B$2:$B$500=$A30),--('Week 2 Schedule'!$D$2:$D$500=$G$28),--('Week 2 Schedule'!$C$2:$C$500>'Week 2 Schedule'!$E$2:$E$500))+SUMPRODUCT(--('Week 2 Schedule'!$B$2:$B$500=$G$28),--('Week 2 Schedule'!$D$2:$D$500=$A30),--('Week 2 Schedule'!$E$2:$E$500>'Week 2 Schedule'!$C$2:$C$500)))+(SUMPRODUCT(--('Week 2 Schedule'!$G$2:$G$500=$A30),--('Week 2 Schedule'!$I$2:$I$500=$G$28),--('Week 2 Schedule'!$H$2:$H$500>'Week 2 Schedule'!$J$2:$J$500))+SUMPRODUCT(--('Week 2 Schedule'!$G$2:$G$500=$G$28),--('Week 2 Schedule'!$I$2:$I$500=$A30),--('Week 2 Schedule'!$J$2:$J$500>'Week 2 Schedule'!$H$2:$H$500)))+(SUMPRODUCT(--('Week 3 Schedule'!$B$2:$B$500=$A30),--('Week 3 Schedule'!$D$2:$D$500=$G$28),--('Week 3 Schedule'!$C$2:$C$500>'Week 3 Schedule'!$E$2:$E$500))+SUMPRODUCT(--('Week 3 Schedule'!$B$2:$B$500=$G$28),--('Week 3 Schedule'!$D$2:$D$500=$A30),--('Week 3 Schedule'!$E$2:$E$500>'Week 3 Schedule'!$C$2:$C$500)))+(SUMPRODUCT(--('Week 3 Schedule'!$G$2:$G$500=$A30),--('Week 3 Schedule'!$I$2:$I$500=$G$28),--('Week 3 Schedule'!$H$2:$H$500>'Week 3 Schedule'!$J$2:$J$500))+SUMPRODUCT(--('Week 3 Schedule'!$G$2:$G$500=$G$28),--('Week 3 Schedule'!$I$2:$I$500=$A30),--('Week 3 Schedule'!$J$2:$J$500>'Week 3 Schedule'!$H$2:$H$500)))+(SUMPRODUCT(--('Week 4 Schedule'!$B$2:$B$500=$A30),--('Week 4 Schedule'!$D$2:$D$500=$G$28),--('Week 4 Schedule'!$C$2:$C$500>'Week 4 Schedule'!$E$2:$E$500))+SUMPRODUCT(--('Week 4 Schedule'!$B$2:$B$500=$G$28),--('Week 4 Schedule'!$D$2:$D$500=$A30),--('Week 4 Schedule'!$E$2:$E$500>'Week 4 Schedule'!$C$2:$C$500)))+(SUMPRODUCT(--('Week 4 Schedule'!$G$2:$G$500=$A30),--('Week 4 Schedule'!$I$2:$I$500=$G$28),--('Week 4 Schedule'!$H$2:$H$500>'Week 4 Schedule'!$J$2:$J$500))+SUMPRODUCT(--('Week 4 Schedule'!$G$2:$G$500=$G$28),--('Week 4 Schedule'!$I$2:$I$500=$A30),--('Week 4 Schedule'!$J$2:$J$500>'Week 4 Schedule'!$H$2:$H$500)))+(SUMPRODUCT(--('Week 5 Schedule'!$B$2:$B$500=$A30),--('Week 5 Schedule'!$D$2:$D$500=$G$28),--('Week 5 Schedule'!$C$2:$C$500>'Week 5 Schedule'!$E$2:$E$500))+SUMPRODUCT(--('Week 5 Schedule'!$B$2:$B$500=$G$28),--('Week 5 Schedule'!$D$2:$D$500=$A30),--('Week 5 Schedule'!$E$2:$E$500>'Week 5 Schedule'!$C$2:$C$500)))+(SUMPRODUCT(--('Week 5 Schedule'!$G$2:$G$500=$A30),--('Week 5 Schedule'!$I$2:$I$500=$G$28),--('Week 5 Schedule'!$H$2:$H$500>'Week 5 Schedule'!$J$2:$J$500))+SUMPRODUCT(--('Week 5 Schedule'!$G$2:$G$500=$G$28),--('Week 5 Schedule'!$I$2:$I$500=$A30),--('Week 5 Schedule'!$J$2:$J$500>'Week 5 Schedule'!$H$2:$H$500)))+(SUMPRODUCT(--('Week 6 Schedule'!$B$2:$B$500=$A30),--('Week 6 Schedule'!$D$2:$D$500=$G$28),--('Week 6 Schedule'!$C$2:$C$500>'Week 6 Schedule'!$E$2:$E$500))+SUMPRODUCT(--('Week 6 Schedule'!$B$2:$B$500=$G$28),--('Week 6 Schedule'!$D$2:$D$500=$A30),--('Week 6 Schedule'!$E$2:$E$500>'Week 6 Schedule'!$C$2:$C$500)))+(SUMPRODUCT(--('Week 6 Schedule'!$G$2:$G$500=$A30),--('Week 6 Schedule'!$I$2:$I$500=$G$28),--('Week 6 Schedule'!$H$2:$H$500>'Week 6 Schedule'!$J$2:$J$500))+SUMPRODUCT(--('Week 6 Schedule'!$G$2:$G$500=$G$28),--('Week 6 Schedule'!$I$2:$I$500=$A30),--('Week 6 Schedule'!$J$2:$J$500>'Week 6 Schedule'!$H$2:$H$500))) | H30: =(SUMPRODUCT(--('Week 1 Schedule'!$B$2:$B$500=$A30),--('Week 1 Schedule'!$D$2:$D$500=$H$28),--('Week 1 Schedule'!$C$2:$C$500>'Week 1 Schedule'!$E$2:$E$500))+SUMPRODUCT(--('Week 1 Schedule'!$B$2:$B$500=$H$28),--('Week 1 Schedule'!$D$2:$D$500=$A30),--('Week 1 Schedule'!$E$2:$E$500>'Week 1 Schedule'!$C$2:$C$500)))+(SUMPRODUCT(--('Week 1 Schedule'!$G$2:$G$500=$A30),--('Week 1 Schedule'!$I$2:$I$500=$H$28),--('Week 1 Schedule'!$H$2:$H$500>'Week 1 Schedule'!$J$2:$J$500))+SUMPRODUCT(--('Week 1 Schedule'!$G$2:$G$500=$H$28),--('Week 1 Schedule'!$I$2:$I$500=$A30),--('Week 1 Schedule'!$J$2:$J$500>'Week 1 Schedule'!$H$2:$H$500)))+(SUMPRODUCT(--('Week 2 Schedule'!$B$2:$B$500=$A30),--('Week 2 Schedule'!$D$2:$D$500=$H$28),--('Week 2 Schedule'!$C$2:$C$500>'Week 2 Schedule'!$E$2:$E$500))+SUMPRODUCT(--('Week 2 Schedule'!$B$2:$B$500=$H$28),--('Week 2 Schedule'!$D$2:$D$500=$A30),--('Week 2 Schedule'!$E$2:$E$500>'Week 2 Schedule'!$C$2:$C$500)))+(SUMPRODUCT(--('Week 2 Schedule'!$G$2:$G$500=$A30),--('Week 2 Schedule'!$I$2:$I$500=$H$28),--('Week 2 Schedule'!$H$2:$H$500>'Week 2 Schedule'!$J$2:$J$500))+SUMPRODUCT(--('Week 2 Schedule'!$G$2:$G$500=$H$28),--('Week 2 Schedule'!$I$2:$I$500=$A30),--('Week 2 Schedule'!$J$2:$J$500>'Week 2 Schedule'!$H$2:$H$500)))+(SUMPRODUCT(--('Week 3 Schedule'!$B$2:$B$500=$A30),--('Week 3 Schedule'!$D$2:$D$500=$H$28),--('Week 3 Schedule'!$C$2:$C$500>'Week 3 Schedule'!$E$2:$E$500))+SUMPRODUCT(--('Week 3 Schedule'!$B$2:$B$500=$H$28),--('Week 3 Schedule'!$D$2:$D$500=$A30),--('Week 3 Schedule'!$E$2:$E$500>'Week 3 Schedule'!$C$2:$C$500)))+(SUMPRODUCT(--('Week 3 Schedule'!$G$2:$G$500=$A30),--('Week 3 Schedule'!$I$2:$I$500=$H$28),--('Week 3 Schedule'!$H$2:$H$500>'Week 3 Schedule'!$J$2:$J$500))+SUMPRODUCT(--('Week 3 Schedule'!$G$2:$G$500=$H$28),--('Week 3 Schedule'!$I$2:$I$500=$A30),--('Week 3 Schedule'!$J$2:$J$500>'Week 3 Schedule'!$H$2:$H$500)))+(SUMPRODUCT(--('Week 4 Schedule'!$B$2:$B$500=$A30),--('Week 4 Schedule'!$D$2:$D$500=$H$28),--('Week 4 Schedule'!$C$2:$C$500>'Week 4 Schedule'!$E$2:$E$500))+SUMPRODUCT(--('Week 4 Schedule'!$B$2:$B$500=$H$28),--('Week 4 Schedule'!$D$2:$D$500=$A30),--('Week 4 Schedule'!$E$2:$E$500>'Week 4 Schedule'!$C$2:$C$500)))+(SUMPRODUCT(--('Week 4 Schedule'!$G$2:$G$500=$A30),--('Week 4 Schedule'!$I$2:$I$500=$H$28),--('Week 4 Schedule'!$H$2:$H$500>'Week 4 Schedule'!$J$2:$J$500))+SUMPRODUCT(--('Week 4 Schedule'!$G$2:$G$500=$H$28),--('Week 4 Schedule'!$I$2:$I$500=$A30),--('Week 4 Schedule'!$J$2:$J$500>'Week 4 Schedule'!$H$2:$H$500)))+(SUMPRODUCT(--('Week 5 Schedule'!$B$2:$B$500=$A30),--('Week 5 Schedule'!$D$2:$D$500=$H$28),--('Week 5 Schedule'!$C$2:$C$500>'Week 5 Schedule'!$E$2:$E$500))+SUMPRODUCT(--('Week 5 Schedule'!$B$2:$B$500=$H$28),--('Week 5 Schedule'!$D$2:$D$500=$A30),--('Week 5 Schedule'!$E$2:$E$500>'Week 5 Schedule'!$C$2:$C$500)))+(SUMPRODUCT(--('Week 5 Schedule'!$G$2:$G$500=$A30),--('Week 5 Schedule'!$I$2:$I$500=$H$28),--('Week 5 Schedule'!$H$2:$H$500>'Week 5 Schedule'!$J$2:$J$500))+SUMPRODUCT(--('Week 5 Schedule'!$G$2:$G$500=$H$28),--('Week 5 Schedule'!$I$2:$I$500=$A30),--('Week 5 Schedule'!$J$2:$J$500>'Week 5 Schedule'!$H$2:$H$500)))+(SUMPRODUCT(--('Week 6 Schedule'!$B$2:$B$500=$A30),--('Week 6 Schedule'!$D$2:$D$500=$H$28),--('Week 6 Schedule'!$C$2:$C$500>'Week 6 Schedule'!$E$2:$E$500))+SUMPRODUCT(--('Week 6 Schedule'!$B$2:$B$500=$H$28),--('Week 6 Schedule'!$D$2:$D$500=$A30),--('Week 6 Schedule'!$E$2:$E$500>'Week 6 Schedule'!$C$2:$C$500)))+(SUMPRODUCT(--('Week 6 Schedule'!$G$2:$G$500=$A30),--('Week 6 Schedule'!$I$2:$I$500=$H$28),--('Week 6 Schedule'!$H$2:$H$500>'Week 6 Schedule'!$J$2:$J$500))+SUMPRODUCT(--('Week 6 Schedule'!$G$2:$G$500=$H$28),--('Week 6 Schedule'!$I$2:$I$500=$A30),--('Week 6 Schedule'!$J$2:$J$500>'Week 6 Schedule'!$H$2:$H$500))) | I30: =(SUMPRODUCT(--('Week 1 Schedule'!$B$2:$B$500=$A30),--('Week 1 Schedule'!$D$2:$D$500=$I$28),--('Week 1 Schedule'!$C$2:$C$500>'Week 1 Schedule'!$E$2:$E$500))+SUMPRODUCT(--('Week 1 Schedule'!$B$2:$B$500=$I$28),--('Week 1 Schedule'!$D$2:$D$500=$A30),--('Week 1 Schedule'!$E$2:$E$500>'Week 1 Schedule'!$C$2:$C$500)))+(SUMPRODUCT(--('Week 1 Schedule'!$G$2:$G$500=$A30),--('Week 1 Schedule'!$I$2:$I$500=$I$28),--('Week 1 Schedule'!$H$2:$H$500>'Week 1 Schedule'!$J$2:$J$500))+SUMPRODUCT(--('Week 1 Schedule'!$G$2:$G$500=$I$28),--('Week 1 Schedule'!$I$2:$I$500=$A30),--('Week 1 Schedule'!$J$2:$J$500>'Week 1 Schedule'!$H$2:$H$500)))+(SUMPRODUCT(--('Week 2 Schedule'!$B$2:$B$500=$A30),--('Week 2 Schedule'!$D$2:$D$500=$I$28),--('Week 2 Schedule'!$C$2:$C$500>'Week 2 Schedule'!$E$2:$E$500))+SUMPRODUCT(--('Week 2 Schedule'!$B$2:$B$500=$I$28),--('Week 2 Schedule'!$D$2:$D$500=$A30),--('Week 2 Schedule'!$E$2:$E$500>'Week 2 Schedule'!$C$2:$C$500)))+(SUMPRODUCT(--('Week 2 Schedule'!$G$2:$G$500=$A30),--('Week 2 Schedule'!$I$2:$I$500=$I$28),--('Week 2 Schedule'!$H$2:$H$500>'Week 2 Schedule'!$J$2:$J$500))+SUMPRODUCT(--('Week 2 Schedule'!$G$2:$G$500=$I$28),--('Week 2 Schedule'!$I$2:$I$500=$A30),--('Week 2 Schedule'!$J$2:$J$500>'Week 2 Schedule'!$H$2:$H$500)))+(SUMPRODUCT(--('Week 3 Schedule'!$B$2:$B$500=$A30),--('Week 3 Schedule'!$D$2:$D$500=$I$28),--('Week 3 Schedule'!$C$2:$C$500>'Week 3 Schedule'!$E$2:$E$500))+SUMPRODUCT(--('Week 3 Schedule'!$B$2:$B$500=$I$28),--('Week 3 Schedule'!$D$2:$D$500=$A30),--('Week 3 Schedule'!$E$2:$E$500>'Week 3 Schedule'!$C$2:$C$500)))+(SUMPRODUCT(--('Week 3 Schedule'!$G$2:$G$500=$A30),--('Week 3 Schedule'!$I$2:$I$500=$I$28),--('Week 3 Schedule'!$H$2:$H$500>'Week 3 Schedule'!$J$2:$J$500))+SUMPRODUCT(--('Week 3 Schedule'!$G$2:$G$500=$I$28),--('Week 3 Schedule'!$I$2:$I$500=$A30),--('Week 3 Schedule'!$J$2:$J$500>'Week 3 Schedule'!$H$2:$H$500)))+(SUMPRODUCT(--('Week 4 Schedule'!$B$2:$B$500=$A30),--('Week 4 Schedule'!$D$2:$D$500=$I$28),--('Week 4 Schedule'!$C$2:$C$500>'Week 4 Schedule'!$E$2:$E$500))+SUMPRODUCT(--('Week 4 Schedule'!$B$2:$B$500=$I$28),--('Week 4 Schedule'!$D$2:$D$500=$A30),--('Week 4 Schedule'!$E$2:$E$500>'Week 4 Schedule'!$C$2:$C$500)))+(SUMPRODUCT(--('Week 4 Schedule'!$G$2:$G$500=$A30),--('Week 4 Schedule'!$I$2:$I$500=$I$28),--('Week 4 Schedule'!$H$2:$H$500>'Week 4 Schedule'!$J$2:$J$500))+SUMPRODUCT(--('Week 4 Schedule'!$G$2:$G$500=$I$28),--('Week 4 Schedule'!$I$2:$I$500=$A30),--('Week 4 Schedule'!$J$2:$J$500>'Week 4 Schedule'!$H$2:$H$500)))+(SUMPRODUCT(--('Week 5 Schedule'!$B$2:$B$500=$A30),--('Week 5 Schedule'!$D$2:$D$500=$I$28),--('Week 5 Schedule'!$C$2:$C$500>'Week 5 Schedule'!$E$2:$E$500))+SUMPRODUCT(--('Week 5 Schedule'!$B$2:$B$500=$I$28),--('Week 5 Schedule'!$D$2:$D$500=$A30),--('Week 5 Schedule'!$E$2:$E$500>'Week 5 Schedule'!$C$2:$C$500)))+(SUMPRODUCT(--('Week 5 Schedule'!$G$2:$G$500=$A30),--('Week 5 Schedule'!$I$2:$I$500=$I$28),--('Week 5 Schedule'!$H$2:$H$500>'Week 5 Schedule'!$J$2:$J$500))+SUMPRODUCT(--('Week 5 Schedule'!$G$2:$G$500=$I$28),--('Week 5 Schedule'!$I$2:$I$500=$A30),--('Week 5 Schedule'!$J$2:$J$500>'Week 5 Schedule'!$H$2:$H$500)))+(SUMPRODUCT(--('Week 6 Schedule'!$B$2:$B$500=$A30),--('Week 6 Schedule'!$D$2:$D$500=$I$28),--('Week 6 Schedule'!$C$2:$C$500>'Week 6 Schedule'!$E$2:$E$500))+SUMPRODUCT(--('Week 6 Schedule'!$B$2:$B$500=$I$28),--('Week 6 Schedule'!$D$2:$D$500=$A30),--('Week 6 Schedule'!$E$2:$E$500>'Week 6 Schedule'!$C$2:$C$500)))+(SUMPRODUCT(--('Week 6 Schedule'!$G$2:$G$500=$A30),--('Week 6 Schedule'!$I$2:$I$500=$I$28),--('Week 6 Schedule'!$H$2:$H$500>'Week 6 Schedule'!$J$2:$J$500))+SUMPRODUCT(--('Week 6 Schedule'!$G$2:$G$500=$I$28),--('Week 6 Schedule'!$I$2:$I$500=$A30),--('Week 6 Schedule'!$J$2:$J$500>'Week 6 Schedule'!$H$2:$H$500)))
